<?xml version="1.0" encoding="utf-8"?>
<!-- This URDF was automatically created by SolidWorks to URDF Exporter! Originally created by Stephen Brawner (brawner@gmail.com) 
     Commit Version: 1.6.0-4-g7f85cfe  Build Version: 1.6.7995.38578
     For more information, please see http://wiki.ros.org/sw_urdf_exporter -->
<robot name="mr5g">
  <link name="world"/>
  <joint name="world_joint" type="fixed">
    <parent link="world"/>
    <child link="base_link"/>
    <origin rpy="0.0 0.0 0.0" xyz="0.0 0.0 0.0"/>
  </joint>
  <link name="base_link">
    <inertial>
      <origin xyz="0.000120857035020885 1.27625939194805E-05 0.0407725510365502" rpy="0 0 0" />
      <mass value="0.54020971947067" />
      <inertia ixx="0.000846965264841098" ixy="-1.0168447774119E-06" ixz="-9.0955653743172E-07" iyy="0.000847130138558194" iyz="-1.65960554550893E-07" izz="0.0012946816639509" />
    </inertial>
    <visual>
      <origin xyz="0 0 0" rpy="0 0 0" />
      <geometry>
        <mesh filename="package://mr5g_description/meshes/base.STL" />
      </geometry>
      <material name="">
        <color rgba="1 0.168627450980392 0.168627450980392 1" />
      </material>
    </visual>
    <collision>
      <origin xyz="0 0 0" rpy="0 0 0" />
      <geometry>
        <mesh filename="package://mr5g_description/meshes/base.STL" />
      </geometry>
    </collision>
  </link>
  <link name="mr5g_link_1">
    <inertial>
      <origin xyz="-0.0028824 0.010502 0.15415" rpy="0 0 0" />
      <mass value="0.96205" />
      <inertia ixx="0.0026857" ixy="-0.00014607" ixz="-1.4162E-05" iyy="0.0031817" iyz="5.1655E-05" izz="0.0013865" />
    </inertial>
    <visual>
      <origin xyz="0 0 0" rpy="0 0 0" />
      <geometry>
        <mesh filename="package://mr5g_description/meshes/axis_1.STL" />
      </geometry>
      <material name="">
        <color rgba="1 0.168627450980392 0.168627450980392 1" />
      </material>
    </visual>
    <collision>
      <origin xyz="0 0 0" rpy="0 0 0" />
      <geometry>
        <mesh filename="package://mr5g_description/meshes/axis_1.STL" />
      </geometry>
    </collision>
  </link>
  <joint name="mr5g_joint_1" type="revolute">
    <origin xyz="0 0 0.15023" rpy="0 0 0" />
    <parent link="base_link" />
    <child link="mr5g_link_1" />
    <axis xyz="0 0 -1" />
    <limit effort="40.0" lower="-3.141592653589793" upper="3.141592653589793" velocity="3.15"/>
  </joint>
  <link name="mr5g_link_2">
    <inertial>
      <origin xyz="-1.6528E-05 -0.18417 0.0039221" rpy="0 0 0" />
      <mass value="1.0951" />
      <inertia ixx="0.0031473" ixy="7.3236E-08" ixz="9.9783E-08" iyy="0.001569" iyz="9.2119E-05" izz="0.003777" />
    </inertial>
    <visual>
      <origin xyz="0 0 0" rpy="0 0 0" />
      <geometry>
        <mesh filename="package://mr5g_description/meshes/axis_2.STL" />
      </geometry>
      <material name="">
        <color rgba="1 0.16863 0.16863 1" />
      </material>
    </visual>
    <collision>
      <origin xyz="0 0 0" rpy="0 0 0" />
      <geometry>
        <mesh filename="package://mr5g_description/meshes/axis_2.STL" />
      </geometry>
    </collision>
  </link>
  <joint name="mr5g_joint_2" type="revolute">
    <!-- <origin xyz="0 0 0.2002" rpy="-1.5708 0 0.26637" /> -->
    <origin xyz="0 0 0.2002" rpy="-1.5708 0 0" />
    <parent link="mr5g_link_1" />
    <child link="mr5g_link_2" />
    <axis xyz="0 0 -1" />
    <limit effort="40.0" lower="-2.15" upper="2.15" velocity="3"/>
  </joint>
  <link name="mr5g_link_3">
    <inertial>
      <origin xyz="-4.1879E-06 -0.15299 -0.0082086" rpy="0 0 0" />
      <mass value="0.72559" />
      <inertia ixx="0.0013472" ixy="2.5553E-09" ixz="-3.1858E-07" iyy="0.0010649" iyz="0.00014569" izz="0.0013311" />
    </inertial>
    <visual>
      <origin xyz="0 0 0" rpy="0 0 0" />
      <geometry>
        <mesh filename="package://mr5g_description/meshes/axis_3.STL" />
      </geometry>
      <material name="">
        <color rgba="1 0.16863 0.16863 1" />
      </material>
    </visual>
    <collision>
      <origin xyz="0 0 0" rpy="0 0 0" />
      <geometry>
        <mesh filename="package://mr5g_description/meshes/axis_3.STL" />
      </geometry>
    </collision>
  </link>
  <joint name="mr5g_joint_3" type="revolute">
    <origin xyz="0 -0.2542 0" rpy="0 0 0" />
    <parent link="mr5g_link_2" />
    <child link="mr5g_link_3" />
    <axis xyz="0 0 -1" />
    <limit effort="25.0" lower="-2.15" upper="2.15" velocity="3"/>
  </joint>
  <link name="mr5g_link_4">
    <inertial>
      <origin xyz="0.00096165 0.0053198 0.11439" rpy="0 0 0" />
      <mass value="0.66116" />
      <inertia ixx="0.0012851" ixy="4.2167E-05" ixz="2.8238E-06" iyy="0.0015089" iyz="1.4011E-05" izz="0.00075918" />
    </inertial>
    <visual>
      <origin xyz="0 0 0" rpy="0 0 0" />
      <geometry>
        <mesh filename="package://mr5g_description/meshes/axis_4.STL" />
      </geometry>
      <material name="">
        <color rgba="1 0.168627450980392 0.168627450980392 1" />
      </material>
    </visual>
    <collision>
      <origin xyz="0 0 0" rpy="0 0 0" />
      <geometry>
        <mesh filename="package://mr5g_description/meshes/axis_4.STL" />
      </geometry>
    </collision>
  </link>
  <joint name="mr5g_joint_4" type="revolute">
    <origin xyz="0 -0.25172 0.0012681" rpy="1.5708 0 0" />
    <parent link="mr5g_link_3" />
    <child link="mr5g_link_4" />
    <axis xyz="0 0 1" />
    <limit effort="10.0" lower="-3.141592653589793" upper="3.141592653589793" velocity="3"/>
  </joint>
  <link name="mr5g_link_5">
    <inertial>
      <origin xyz="4.9788044054048E-06 -0.0361608588367326 -0.0279972199896629" rpy="0 0 0" />
      <mass value="0.327558781213899" />
      <inertia ixx="0.000662565752292812" ixy="-3.03329073594475E-09" ixz="-1.99440015526418E-08" iyy="0.000387603430781861" iyz="0.00017563188243387" izz="0.00068888720705538" />
    </inertial>
    <visual>
      <origin xyz="0 0 0" rpy="0 0 0" />
      <geometry>
        <mesh filename="package://mr5g_description/meshes/axis_5.STL" />
      </geometry>
      <material name="">
        <color rgba="1 0.168627450980392 0.168627450980392 1" />
      </material>
    </visual>
    <collision>
      <origin xyz="0 0 0" rpy="0 0 0" />
      <geometry>
        <mesh filename="package://mr5g_description/meshes/axis_5.STL" />
      </geometry>
    </collision>
  </link>
  <joint name="mr5g_joint_5" type="revolute">
    <!-- <origin xyz="0 0 0.1641" rpy="-1.5708 0 -0.18001" /> -->
    <origin xyz="0 0 0.1641" rpy="-1.5708 0 0" />
    <parent link="mr5g_link_4" />
    <child link="mr5g_link_5" />
    <axis xyz="0 0 -1" />
    <limit effort="20.0" lower="-2.12" upper="2.12" velocity="3"/>
  </joint>

  <joint name="g6_joint_0" type="fixed">
    <origin rpy="1.5708 0 0" xyz="0 -0.096 0"/>
    <parent link="mr5g_link_5"/>
    <child link="g6_palm_link"/>
  </joint>
  <link name="g6_palm_link">
    <visual>
      <origin rpy="0 0 0" xyz="0 0 0"/>
      <geometry>
        <mesh filename="package://mr_description/meshes/g_palm_link.STL"/>
      </geometry>
      <material name="">
        <color rgba="0.1 0.1 0.1 1"/>
      </material>
    </visual>
    <collision>
      <origin rpy="0 0 0" xyz="0 0 0.028"/>
      <geometry>
        <!--        <mesh  filename="package://mr_description/meshes/g_palm_link.STL" />-->
        <cylinder length="0.056" radius="0.0425"/>
      </geometry>
    </collision>
    <inertial>
      <origin rpy="0 0 0" xyz="0.00425087794620391 -0.000341076549934847 0.0434713557042779"/>
      <mass value="0.566653469628951"/>
      <inertia ixx="0.000498497223548746" ixy="5.36329649188159E-07" ixz="-4.07818737202901E-05" iyy="0.000730511793998383" iyz="-6.03266058697901E-06" izz="0.000502182372067087"/>
    </inertial>
  </link>
  <joint name="g6_Joint" type="prismatic">
    <origin rpy="0 0 0" xyz="0 0 0"/>
    <parent link="g6_palm_link"/>
    <child link="g6_finger_link"/>
    <axis xyz="-1 0 0"/>
    <limit effort="1" lower="0" upper="0.06" velocity="0.06"/>
    <!--    <calibration   rising="1"   falling="1" />-->
    <!--    <dynamics    damping="1"    friction="1" />-->
    <!--    <safety_controller soft_upper="0.06" soft_lower="0" k_position="1" k_velocity="1" />-->
  </joint>
  <joint name="g6_Joint1" type="prismatic">
    <origin rpy="0 0 0" xyz="0 0 0"/>
    <parent link="g6_palm_link"/>
    <child link="g6_finger_link1"/>
    <axis xyz="1 0 0"/>
    <limit effort="1" lower="0" upper="0.06" velocity="0.06"/>
    <!--    <calibration  rising="1" />-->
    <!--    <dynamics  damping="1"  friction="1" />-->
    <!--    <safety_controller soft_upper="0.06" soft_lower="0" k_position="1" k_velocity="1" />-->
  </joint>
  <link name="g6_finger_link">
    <visual>
      <origin rpy="0 0 0" xyz="0 0 0"/>
      <geometry>
        <mesh filename="package://mr_description/meshes/g_finger_link.STL"/>
      </geometry>
      <material name="">
        <color rgba="0.1 0.1 0.1 1"/>
      </material>
    </visual>
    <collision>
      <origin rpy="0 0 0" xyz="0 0 0"/>
      <geometry>
        <mesh filename="package://mr_description/meshes/g_finger_link.STL"/>
      </geometry>
    </collision>
    <inertial>
      <origin rpy="0 0 0" xyz="-0.0142537929479308 0.000230061402547915 0.123240994639791"/>
      <mass value="0.0587979869361216"/>
      <inertia ixx="4.06347072846223E-05" ixy="2.52194515964668E-08" ixz="9.16297919180235E-06" iyy="4.29642140065611E-05" iyz="3.2622913893542E-08" izz="9.72727638920999E-06"/>
    </inertial>
  </link>
  <link name="g6_finger_link1">
    <visual>
      <origin rpy="0 0 0" xyz="0 0 0"/>
      <geometry>
        <mesh filename="package://mr_description/meshes/g_finger_link1.STL"/>
      </geometry>
      <material name="">
        <color rgba="0.1 0.1 0.1 1"/>
      </material>
    </visual>
    <collision>
      <origin rpy="0 0 0" xyz="0 0 0"/>
      <geometry>
        <mesh filename="package://mr_description/meshes/g_finger_link1.STL"/>
      </geometry>
    </collision>
    <inertial>
      <origin rpy="0 0 0" xyz="0.0142537929479934 3.43816122645394E-05 0.123240994639808"/>
      <mass value="0.0587979869361215"/>
      <inertia ixx="4.06348713317454E-05" ixy="4.84294028883443E-09" ixz="-9.16297919179846E-06" iyy="4.29642140065595E-05" iyz="-7.56625401696782E-08" izz="9.72744043633773E-06"/>
    </inertial>
  </link>
  <joint name="tcp_fixed_joint" type="fixed">
    <origin rpy="0 0 0" xyz="0 0 0.16"/>
    <parent link="g6_palm_link"/>
    <child link="tcp_link"/>
  </joint>
  <link name="tcp_link"/>
</robot>
